[2024-08-11T09:12:05.533+0000] {local_task_job_runner.py:120} INFO - ::group::Pre task execution logs
[2024-08-11T09:12:05.586+0000] {taskinstance.py:2076} INFO - Dependencies all met for dep_context=non-requeueable deps ti=<TaskInstance: simple_dag.send_email manual__2024-08-11T08:59:40.495774+00:00 [queued]>
[2024-08-11T09:12:05.611+0000] {taskinstance.py:2076} INFO - Dependencies all met for dep_context=requeueable deps ti=<TaskInstance: simple_dag.send_email manual__2024-08-11T08:59:40.495774+00:00 [queued]>
[2024-08-11T09:12:05.613+0000] {taskinstance.py:2306} INFO - Starting attempt 2 of 2
[2024-08-11T09:12:05.658+0000] {taskinstance.py:2330} INFO - Executing <Task(EmailOperator): send_email> on 2024-08-11 08:59:40.495774+00:00
[2024-08-11T09:12:05.679+0000] {warnings.py:112} WARNING - /home/***/.local/lib/python3.12/site-packages/***/task/task_runner/standard_task_runner.py:62: DeprecationWarning: This process (pid=5780) is multi-threaded, use of fork() may lead to deadlocks in the child.
  pid = os.fork()

[2024-08-11T09:12:05.684+0000] {standard_task_runner.py:64} INFO - Started process 5782 to run task
[2024-08-11T09:12:05.683+0000] {standard_task_runner.py:90} INFO - Running: ['***', 'tasks', 'run', 'simple_dag', 'send_email', 'manual__2024-08-11T08:59:40.495774+00:00', '--job-id', '179', '--raw', '--subdir', 'DAGS_FOLDER/envioemail.py', '--cfg-path', '/tmp/tmp05_cakq8']
[2024-08-11T09:12:05.691+0000] {standard_task_runner.py:91} INFO - Job 179: Subtask send_email
[2024-08-11T09:12:05.811+0000] {task_command.py:426} INFO - Running <TaskInstance: simple_dag.send_email manual__2024-08-11T08:59:40.495774+00:00 [running]> on host 18efa902f572
[2024-08-11T09:12:06.008+0000] {taskinstance.py:2648} INFO - Exporting env vars: AIRFLOW_CTX_DAG_OWNER='***' AIRFLOW_CTX_DAG_ID='simple_dag' AIRFLOW_CTX_TASK_ID='send_email' AIRFLOW_CTX_EXECUTION_DATE='2024-08-11T08:59:40.495774+00:00' AIRFLOW_CTX_TRY_NUMBER='2' AIRFLOW_CTX_DAG_RUN_ID='manual__2024-08-11T08:59:40.495774+00:00'
[2024-08-11T09:12:06.011+0000] {taskinstance.py:430} INFO - ::endgroup::
[2024-08-11T09:12:06.058+0000] {base.py:84} INFO - Using connection ID 'smtp_default' for task execution.
[2024-08-11T09:12:06.060+0000] {email.py:271} INFO - Email alerting: attempt 1
[2024-08-11T09:12:06.062+0000] {taskinstance.py:441} INFO - ::group::Post task execution logs
[2024-08-11T09:12:06.063+0000] {taskinstance.py:2905} ERROR - Task failed with exception
Traceback (most recent call last):
  File "/home/airflow/.local/lib/python3.12/site-packages/airflow/models/taskinstance.py", line 465, in _execute_task
    result = _execute_callable(context=context, **execute_callable_kwargs)
             ^^^^^^^^^^^^^^^^^^^^^^^^^^^^^^^^^^^^^^^^^^^^^^^^^^^^^^^^^^^^^
  File "/home/airflow/.local/lib/python3.12/site-packages/airflow/models/taskinstance.py", line 432, in _execute_callable
    return execute_callable(context=context, **execute_callable_kwargs)
           ^^^^^^^^^^^^^^^^^^^^^^^^^^^^^^^^^^^^^^^^^^^^^^^^^^^^^^^^^^^^
  File "/home/airflow/.local/lib/python3.12/site-packages/airflow/models/baseoperator.py", line 401, in wrapper
    return func(self, *args, **kwargs)
           ^^^^^^^^^^^^^^^^^^^^^^^^^^^
  File "/home/airflow/.local/lib/python3.12/site-packages/airflow/operators/email.py", line 79, in execute
    send_email(
  File "/home/airflow/.local/lib/python3.12/site-packages/airflow/utils/email.py", line 80, in send_email
    return backend(
           ^^^^^^^^
  File "/home/airflow/.local/lib/python3.12/site-packages/airflow/utils/email.py", line 154, in send_email_smtp
    send_mime_email(e_from=mail_from, e_to=recipients, mime_msg=msg, conn_id=conn_id, dryrun=dryrun)
  File "/home/airflow/.local/lib/python3.12/site-packages/airflow/utils/email.py", line 273, in send_mime_email
    smtp_conn = _get_smtp_connection(smtp_host, smtp_port, smtp_timeout, smtp_ssl)
                ^^^^^^^^^^^^^^^^^^^^^^^^^^^^^^^^^^^^^^^^^^^^^^^^^^^^^^^^^^^^^^^^^^
  File "/home/airflow/.local/lib/python3.12/site-packages/airflow/utils/email.py", line 317, in _get_smtp_connection
    return smtplib.SMTP(host=host, port=port, timeout=timeout)
           ^^^^^^^^^^^^^^^^^^^^^^^^^^^^^^^^^^^^^^^^^^^^^^^^^^^
  File "/usr/local/lib/python3.12/smtplib.py", line 255, in __init__
    (code, msg) = self.connect(host, port)
                  ^^^^^^^^^^^^^^^^^^^^^^^^
  File "/usr/local/lib/python3.12/smtplib.py", line 341, in connect
    self.sock = self._get_socket(host, port, self.timeout)
                ^^^^^^^^^^^^^^^^^^^^^^^^^^^^^^^^^^^^^^^^^^
  File "/usr/local/lib/python3.12/smtplib.py", line 312, in _get_socket
    return socket.create_connection((host, port), timeout,
           ^^^^^^^^^^^^^^^^^^^^^^^^^^^^^^^^^^^^^^^^^^^^^^^
  File "/usr/local/lib/python3.12/socket.py", line 853, in create_connection
    raise exceptions[0]
  File "/usr/local/lib/python3.12/socket.py", line 838, in create_connection
    sock.connect(sa)
ConnectionRefusedError: [Errno 111] Connection refused
[2024-08-11T09:12:06.077+0000] {taskinstance.py:1206} INFO - Marking task as FAILED. dag_id=simple_dag, task_id=send_email, run_id=manual__2024-08-11T08:59:40.495774+00:00, execution_date=20240811T085940, start_date=20240811T091205, end_date=20240811T091206
[2024-08-11T09:12:06.099+0000] {standard_task_runner.py:110} ERROR - Failed to execute job 179 for task send_email ([Errno 111] Connection refused; 5782)
[2024-08-11T09:12:06.144+0000] {local_task_job_runner.py:243} INFO - Task exited with return code 1
[2024-08-11T09:12:06.195+0000] {taskinstance.py:3503} INFO - 0 downstream tasks scheduled from follow-on schedule check
[2024-08-11T09:12:06.200+0000] {local_task_job_runner.py:222} INFO - ::endgroup::
