[2024-08-31T16:27:38.175+0000] {local_task_job_runner.py:120} INFO - ::group::Pre task execution logs
[2024-08-31T16:27:38.865+0000] {taskinstance.py:2076} INFO - Dependencies all met for dep_context=non-requeueable deps ti=<TaskInstance: simple_dag.tarea_fallida manual__2024-08-31T16:27:32.704103+00:00 [queued]>
[2024-08-31T16:27:38.897+0000] {taskinstance.py:2076} INFO - Dependencies all met for dep_context=requeueable deps ti=<TaskInstance: simple_dag.tarea_fallida manual__2024-08-31T16:27:32.704103+00:00 [queued]>
[2024-08-31T16:27:38.900+0000] {taskinstance.py:2306} INFO - Starting attempt 1 of 2
[2024-08-31T16:27:38.963+0000] {taskinstance.py:2330} INFO - Executing <Task(PythonOperator): tarea_fallida> on 2024-08-31 16:27:32.704103+00:00
[2024-08-31T16:27:38.988+0000] {warnings.py:112} WARNING - /home/***/.local/lib/python3.12/site-packages/***/task/task_runner/standard_task_runner.py:62: DeprecationWarning: This process (pid=2193) is multi-threaded, use of fork() may lead to deadlocks in the child.
  pid = os.fork()

[2024-08-31T16:27:38.994+0000] {standard_task_runner.py:64} INFO - Started process 2195 to run task
[2024-08-31T16:27:38.995+0000] {standard_task_runner.py:90} INFO - Running: ['***', 'tasks', 'run', 'simple_dag', 'tarea_fallida', 'manual__2024-08-31T16:27:32.704103+00:00', '--job-id', '326', '--raw', '--subdir', 'DAGS_FOLDER/envioemail.py', '--cfg-path', '/tmp/tmpkcgbmp2u']
[2024-08-31T16:27:39.003+0000] {standard_task_runner.py:91} INFO - Job 326: Subtask tarea_fallida
[2024-08-31T16:27:39.293+0000] {task_command.py:426} INFO - Running <TaskInstance: simple_dag.tarea_fallida manual__2024-08-31T16:27:32.704103+00:00 [running]> on host 19bb8daff211
[2024-08-31T16:27:39.904+0000] {taskinstance.py:2648} INFO - Exporting env vars: AIRFLOW_CTX_DAG_EMAIL='jorgepons90@gmail.com,facturasjorgepons@gmail.com' AIRFLOW_CTX_DAG_OWNER='Jorge Pons' AIRFLOW_CTX_DAG_ID='simple_dag' AIRFLOW_CTX_TASK_ID='tarea_fallida' AIRFLOW_CTX_EXECUTION_DATE='2024-08-31T16:27:32.704103+00:00' AIRFLOW_CTX_TRY_NUMBER='1' AIRFLOW_CTX_DAG_RUN_ID='manual__2024-08-31T16:27:32.704103+00:00'
[2024-08-31T16:27:39.914+0000] {taskinstance.py:430} INFO - ::endgroup::
[2024-08-31T16:27:40.056+0000] {taskinstance.py:441} INFO - ::group::Post task execution logs
[2024-08-31T16:27:40.059+0000] {taskinstance.py:2905} ERROR - Task failed with exception
Traceback (most recent call last):
  File "/home/airflow/.local/lib/python3.12/site-packages/airflow/models/taskinstance.py", line 465, in _execute_task
    result = _execute_callable(context=context, **execute_callable_kwargs)
             ^^^^^^^^^^^^^^^^^^^^^^^^^^^^^^^^^^^^^^^^^^^^^^^^^^^^^^^^^^^^^
  File "/home/airflow/.local/lib/python3.12/site-packages/airflow/models/taskinstance.py", line 432, in _execute_callable
    return execute_callable(context=context, **execute_callable_kwargs)
           ^^^^^^^^^^^^^^^^^^^^^^^^^^^^^^^^^^^^^^^^^^^^^^^^^^^^^^^^^^^^
  File "/home/airflow/.local/lib/python3.12/site-packages/airflow/models/baseoperator.py", line 401, in wrapper
    return func(self, *args, **kwargs)
           ^^^^^^^^^^^^^^^^^^^^^^^^^^^
  File "/home/airflow/.local/lib/python3.12/site-packages/airflow/operators/python.py", line 235, in execute
    return_value = self.execute_callable()
                   ^^^^^^^^^^^^^^^^^^^^^^^
  File "/home/airflow/.local/lib/python3.12/site-packages/airflow/operators/python.py", line 252, in execute_callable
    return self.python_callable(*self.op_args, **self.op_kwargs)
           ^^^^^^^^^^^^^^^^^^^^^^^^^^^^^^^^^^^^^^^^^^^^^^^^^^^^^
  File "/opt/airflow/dags/envioemail.py", line 29, in mi_funcion
    raise ValueError("¡Algo salió mal!")
ValueError: ¡Algo salió mal!
[2024-08-31T16:27:40.114+0000] {taskinstance.py:1206} INFO - Marking task as UP_FOR_RETRY. dag_id=simple_dag, task_id=tarea_fallida, run_id=manual__2024-08-31T16:27:32.704103+00:00, execution_date=20240831T162732, start_date=20240831T162738, end_date=20240831T162740
[2024-08-31T16:27:40.218+0000] {standard_task_runner.py:110} ERROR - Failed to execute job 326 for task tarea_fallida (¡Algo salió mal!; 2195)
[2024-08-31T16:27:40.307+0000] {local_task_job_runner.py:243} INFO - Task exited with return code 1
[2024-08-31T16:27:40.479+0000] {taskinstance.py:3503} INFO - 0 downstream tasks scheduled from follow-on schedule check
[2024-08-31T16:27:40.504+0000] {local_task_job_runner.py:222} INFO - ::endgroup::
