[2024-08-29T15:17:38.177+0000] {local_task_job_runner.py:120} INFO - ::group::Pre task execution logs
[2024-08-29T15:17:38.421+0000] {taskinstance.py:2076} INFO - Dependencies all met for dep_context=non-requeueable deps ti=<TaskInstance: simple_dag.get_data manual__2024-08-29T15:17:36.388127+00:00 [queued]>
[2024-08-29T15:17:38.433+0000] {taskinstance.py:2076} INFO - Dependencies all met for dep_context=requeueable deps ti=<TaskInstance: simple_dag.get_data manual__2024-08-29T15:17:36.388127+00:00 [queued]>
[2024-08-29T15:17:38.435+0000] {taskinstance.py:2306} INFO - Starting attempt 1 of 2
[2024-08-29T15:17:38.456+0000] {taskinstance.py:2330} INFO - Executing <Task(PythonOperator): get_data> on 2024-08-29 15:17:36.388127+00:00
[2024-08-29T15:17:38.464+0000] {warnings.py:112} WARNING - /home/***/.local/lib/python3.12/site-packages/***/task/task_runner/standard_task_runner.py:62: DeprecationWarning: This process (pid=372) is multi-threaded, use of fork() may lead to deadlocks in the child.
  pid = os.fork()

[2024-08-29T15:17:38.466+0000] {standard_task_runner.py:64} INFO - Started process 374 to run task
[2024-08-29T15:17:38.466+0000] {standard_task_runner.py:90} INFO - Running: ['***', 'tasks', 'run', 'simple_dag', 'get_data', 'manual__2024-08-29T15:17:36.388127+00:00', '--job-id', '286', '--raw', '--subdir', 'DAGS_FOLDER/envioemail.py', '--cfg-path', '/tmp/tmpqmvd4mdu']
[2024-08-29T15:17:38.469+0000] {standard_task_runner.py:91} INFO - Job 286: Subtask get_data
[2024-08-29T15:17:38.528+0000] {task_command.py:426} INFO - Running <TaskInstance: simple_dag.get_data manual__2024-08-29T15:17:36.388127+00:00 [running]> on host 00cc7a82b56e
[2024-08-29T15:17:38.658+0000] {taskinstance.py:2648} INFO - Exporting env vars: AIRFLOW_CTX_DAG_OWNER='***' AIRFLOW_CTX_DAG_ID='simple_dag' AIRFLOW_CTX_TASK_ID='get_data' AIRFLOW_CTX_EXECUTION_DATE='2024-08-29T15:17:36.388127+00:00' AIRFLOW_CTX_TRY_NUMBER='1' AIRFLOW_CTX_DAG_RUN_ID='manual__2024-08-29T15:17:36.388127+00:00'
[2024-08-29T15:17:38.661+0000] {taskinstance.py:430} INFO - ::endgroup::
[2024-08-29T15:17:38.699+0000] {base.py:84} INFO - Using connection ID 'my_mssql_conn_id' for task execution.
[2024-08-29T15:17:59.731+0000] {taskinstance.py:441} INFO - ::group::Post task execution logs
[2024-08-29T15:17:59.733+0000] {taskinstance.py:2905} ERROR - Task failed with exception
Traceback (most recent call last):
  File "src/pymssql/_pymssql.pyx", line 650, in pymssql._pymssql.connect
  File "src/pymssql/_mssql.pyx", line 2155, in pymssql._mssql.connect
  File "src/pymssql/_mssql.pyx", line 712, in pymssql._mssql.MSSQLConnection.__init__
  File "src/pymssql/_mssql.pyx", line 1881, in pymssql._mssql.maybe_raise_MSSQLDatabaseException
  File "src/pymssql/_mssql.pyx", line 1898, in pymssql._mssql.raise_MSSQLDatabaseException
pymssql._mssql.MSSQLDatabaseException: (20009, b'DB-Lib error message 20009, severity 9:\nUnable to connect: Adaptive Server is unavailable or does not exist (192.168.1.146)\nNet-Lib error during Connection refused (111)\nDB-Lib error message 20009, severity 9:\nUnable to connect: Adaptive Server is unavailable or does not exist (192.168.1.146)\nNet-Lib error during Connection refused (111)\n')

During handling of the above exception, another exception occurred:

Traceback (most recent call last):
  File "/home/airflow/.local/lib/python3.12/site-packages/airflow/models/taskinstance.py", line 465, in _execute_task
    result = _execute_callable(context=context, **execute_callable_kwargs)
             ^^^^^^^^^^^^^^^^^^^^^^^^^^^^^^^^^^^^^^^^^^^^^^^^^^^^^^^^^^^^^
  File "/home/airflow/.local/lib/python3.12/site-packages/airflow/models/taskinstance.py", line 432, in _execute_callable
    return execute_callable(context=context, **execute_callable_kwargs)
           ^^^^^^^^^^^^^^^^^^^^^^^^^^^^^^^^^^^^^^^^^^^^^^^^^^^^^^^^^^^^
  File "/home/airflow/.local/lib/python3.12/site-packages/airflow/models/baseoperator.py", line 401, in wrapper
    return func(self, *args, **kwargs)
           ^^^^^^^^^^^^^^^^^^^^^^^^^^^
  File "/home/airflow/.local/lib/python3.12/site-packages/airflow/operators/python.py", line 235, in execute
    return_value = self.execute_callable()
                   ^^^^^^^^^^^^^^^^^^^^^^^
  File "/home/airflow/.local/lib/python3.12/site-packages/airflow/operators/python.py", line 252, in execute_callable
    return self.python_callable(*self.op_args, **self.op_kwargs)
           ^^^^^^^^^^^^^^^^^^^^^^^^^^^^^^^^^^^^^^^^^^^^^^^^^^^^^
  File "/opt/airflow/dags/funciones.py", line 21, in query_mssql
    conn = pymssql.connect(server=host, user=username, password=password, database=database)
           ^^^^^^^^^^^^^^^^^^^^^^^^^^^^^^^^^^^^^^^^^^^^^^^^^^^^^^^^^^^^^^^^^^^^^^^^^^^^^^^^^
  File "src/pymssql/_pymssql.pyx", line 659, in pymssql._pymssql.connect
pymssql.exceptions.OperationalError: (20009, b'DB-Lib error message 20009, severity 9:\nUnable to connect: Adaptive Server is unavailable or does not exist (192.168.1.146)\nNet-Lib error during Connection refused (111)\nDB-Lib error message 20009, severity 9:\nUnable to connect: Adaptive Server is unavailable or does not exist (192.168.1.146)\nNet-Lib error during Connection refused (111)\n')
[2024-08-29T15:17:59.760+0000] {taskinstance.py:1206} INFO - Marking task as UP_FOR_RETRY. dag_id=simple_dag, task_id=get_data, run_id=manual__2024-08-29T15:17:36.388127+00:00, execution_date=20240829T151736, start_date=20240829T151738, end_date=20240829T151759
[2024-08-29T15:17:59.782+0000] {standard_task_runner.py:110} ERROR - Failed to execute job 286 for task get_data ((20009, b'DB-Lib error message 20009, severity 9:\nUnable to connect: Adaptive Server is unavailable or does not exist (192.168.1.146)\nNet-Lib error during Connection refused (111)\nDB-Lib error message 20009, severity 9:\nUnable to connect: Adaptive Server is unavailable or does not exist (192.168.1.146)\nNet-Lib error during Connection refused (111)\n'); 374)
[2024-08-29T15:17:59.803+0000] {local_task_job_runner.py:243} INFO - Task exited with return code 1
[2024-08-29T15:17:59.815+0000] {local_task_job_runner.py:222} INFO - ::endgroup::
