[2024-08-27T11:31:04.448+0000] {local_task_job_runner.py:120} INFO - ::group::Pre task execution logs
[2024-08-27T11:31:04.708+0000] {taskinstance.py:2076} INFO - Dependencies all met for dep_context=non-requeueable deps ti=<TaskInstance: simple_dag.send_email scheduled__2024-08-26T00:00:00+00:00 [queued]>
[2024-08-27T11:31:04.858+0000] {taskinstance.py:2076} INFO - Dependencies all met for dep_context=requeueable deps ti=<TaskInstance: simple_dag.send_email scheduled__2024-08-26T00:00:00+00:00 [queued]>
[2024-08-27T11:31:04.873+0000] {taskinstance.py:2306} INFO - Starting attempt 1 of 2
[2024-08-27T11:31:05.046+0000] {taskinstance.py:2330} INFO - Executing <Task(EmailOperator): send_email> on 2024-08-26 00:00:00+00:00
[2024-08-27T11:31:05.092+0000] {warnings.py:112} WARNING - /home/***/.local/lib/python3.12/site-packages/***/task/task_runner/standard_task_runner.py:62: DeprecationWarning: This process (pid=106) is multi-threaded, use of fork() may lead to deadlocks in the child.
  pid = os.fork()

[2024-08-27T11:31:05.107+0000] {standard_task_runner.py:90} INFO - Running: ['***', 'tasks', 'run', 'simple_dag', 'send_email', 'scheduled__2024-08-26T00:00:00+00:00', '--job-id', '268', '--raw', '--subdir', 'DAGS_FOLDER/envioemail.py', '--cfg-path', '/tmp/tmp9xzt00t7']
[2024-08-27T11:31:05.125+0000] {standard_task_runner.py:64} INFO - Started process 111 to run task
[2024-08-27T11:31:05.126+0000] {standard_task_runner.py:91} INFO - Job 268: Subtask send_email
[2024-08-27T11:31:05.617+0000] {task_command.py:426} INFO - Running <TaskInstance: simple_dag.send_email scheduled__2024-08-26T00:00:00+00:00 [running]> on host 808fca4309cb
[2024-08-27T11:31:06.093+0000] {taskinstance.py:2648} INFO - Exporting env vars: AIRFLOW_CTX_DAG_OWNER='***' AIRFLOW_CTX_DAG_ID='simple_dag' AIRFLOW_CTX_TASK_ID='send_email' AIRFLOW_CTX_EXECUTION_DATE='2024-08-26T00:00:00+00:00' AIRFLOW_CTX_TRY_NUMBER='1' AIRFLOW_CTX_DAG_RUN_ID='scheduled__2024-08-26T00:00:00+00:00'
[2024-08-27T11:31:06.097+0000] {taskinstance.py:430} INFO - ::endgroup::
[2024-08-27T11:31:06.248+0000] {base.py:84} INFO - Using connection ID 'smtp_default' for task execution.
[2024-08-27T11:31:06.256+0000] {email.py:271} INFO - Email alerting: attempt 1
[2024-08-27T11:31:06.260+0000] {taskinstance.py:441} INFO - ::group::Post task execution logs
[2024-08-27T11:31:06.262+0000] {taskinstance.py:2905} ERROR - Task failed with exception
Traceback (most recent call last):
  File "/home/airflow/.local/lib/python3.12/site-packages/airflow/models/taskinstance.py", line 465, in _execute_task
    result = _execute_callable(context=context, **execute_callable_kwargs)
             ^^^^^^^^^^^^^^^^^^^^^^^^^^^^^^^^^^^^^^^^^^^^^^^^^^^^^^^^^^^^^
  File "/home/airflow/.local/lib/python3.12/site-packages/airflow/models/taskinstance.py", line 432, in _execute_callable
    return execute_callable(context=context, **execute_callable_kwargs)
           ^^^^^^^^^^^^^^^^^^^^^^^^^^^^^^^^^^^^^^^^^^^^^^^^^^^^^^^^^^^^
  File "/home/airflow/.local/lib/python3.12/site-packages/airflow/models/baseoperator.py", line 401, in wrapper
    return func(self, *args, **kwargs)
           ^^^^^^^^^^^^^^^^^^^^^^^^^^^
  File "/home/airflow/.local/lib/python3.12/site-packages/airflow/operators/email.py", line 79, in execute
    send_email(
  File "/home/airflow/.local/lib/python3.12/site-packages/airflow/utils/email.py", line 80, in send_email
    return backend(
           ^^^^^^^^
  File "/home/airflow/.local/lib/python3.12/site-packages/airflow/utils/email.py", line 154, in send_email_smtp
    send_mime_email(e_from=mail_from, e_to=recipients, mime_msg=msg, conn_id=conn_id, dryrun=dryrun)
  File "/home/airflow/.local/lib/python3.12/site-packages/airflow/utils/email.py", line 273, in send_mime_email
    smtp_conn = _get_smtp_connection(smtp_host, smtp_port, smtp_timeout, smtp_ssl)
                ^^^^^^^^^^^^^^^^^^^^^^^^^^^^^^^^^^^^^^^^^^^^^^^^^^^^^^^^^^^^^^^^^^
  File "/home/airflow/.local/lib/python3.12/site-packages/airflow/utils/email.py", line 317, in _get_smtp_connection
    return smtplib.SMTP(host=host, port=port, timeout=timeout)
           ^^^^^^^^^^^^^^^^^^^^^^^^^^^^^^^^^^^^^^^^^^^^^^^^^^^
  File "/usr/local/lib/python3.12/smtplib.py", line 255, in __init__
    (code, msg) = self.connect(host, port)
                  ^^^^^^^^^^^^^^^^^^^^^^^^
  File "/usr/local/lib/python3.12/smtplib.py", line 341, in connect
    self.sock = self._get_socket(host, port, self.timeout)
                ^^^^^^^^^^^^^^^^^^^^^^^^^^^^^^^^^^^^^^^^^^
  File "/usr/local/lib/python3.12/smtplib.py", line 312, in _get_socket
    return socket.create_connection((host, port), timeout,
           ^^^^^^^^^^^^^^^^^^^^^^^^^^^^^^^^^^^^^^^^^^^^^^^
  File "/usr/local/lib/python3.12/socket.py", line 853, in create_connection
    raise exceptions[0]
  File "/usr/local/lib/python3.12/socket.py", line 838, in create_connection
    sock.connect(sa)
ConnectionRefusedError: [Errno 111] Connection refused
[2024-08-27T11:31:06.294+0000] {taskinstance.py:1206} INFO - Marking task as UP_FOR_RETRY. dag_id=simple_dag, task_id=send_email, run_id=scheduled__2024-08-26T00:00:00+00:00, execution_date=20240826T000000, start_date=20240827T113104, end_date=20240827T113106
[2024-08-27T11:31:06.340+0000] {standard_task_runner.py:110} ERROR - Failed to execute job 268 for task send_email ([Errno 111] Connection refused; 111)
[2024-08-27T11:31:06.403+0000] {local_task_job_runner.py:243} INFO - Task exited with return code 1
[2024-08-27T11:31:06.464+0000] {taskinstance.py:3503} INFO - 0 downstream tasks scheduled from follow-on schedule check
[2024-08-27T11:31:06.471+0000] {local_task_job_runner.py:222} INFO - ::endgroup::
