[2024-08-31T17:51:24.667+0000] {local_task_job_runner.py:120} INFO - ::group::Pre task execution logs
[2024-08-31T17:51:24.937+0000] {taskinstance.py:2076} INFO - Dependencies all met for dep_context=non-requeueable deps ti=<TaskInstance: simple_dag.execution_time manual__2024-08-31T16:50:00.890695+00:00 [queued]>
[2024-08-31T17:51:24.957+0000] {taskinstance.py:2076} INFO - Dependencies all met for dep_context=requeueable deps ti=<TaskInstance: simple_dag.execution_time manual__2024-08-31T16:50:00.890695+00:00 [queued]>
[2024-08-31T17:51:24.961+0000] {taskinstance.py:2306} INFO - Starting attempt 20 of 21
[2024-08-31T17:51:24.991+0000] {taskinstance.py:2330} INFO - Executing <Task(PythonOperator): execution_time> on 2024-08-31 16:50:00.890695+00:00
[2024-08-31T17:51:25.001+0000] {warnings.py:112} WARNING - /home/***/.local/lib/python3.12/site-packages/***/task/task_runner/standard_task_runner.py:62: DeprecationWarning: This process (pid=3291) is multi-threaded, use of fork() may lead to deadlocks in the child.
  pid = os.fork()

[2024-08-31T17:51:25.004+0000] {standard_task_runner.py:64} INFO - Started process 3293 to run task
[2024-08-31T17:51:25.004+0000] {standard_task_runner.py:90} INFO - Running: ['***', 'tasks', 'run', 'simple_dag', 'execution_time', 'manual__2024-08-31T16:50:00.890695+00:00', '--job-id', '350', '--raw', '--subdir', 'DAGS_FOLDER/envioemail.py', '--cfg-path', '/tmp/tmpoic32oyu']
[2024-08-31T17:51:25.009+0000] {standard_task_runner.py:91} INFO - Job 350: Subtask execution_time
[2024-08-31T17:51:25.093+0000] {task_command.py:426} INFO - Running <TaskInstance: simple_dag.execution_time manual__2024-08-31T16:50:00.890695+00:00 [running]> on host 19bb8daff211
[2024-08-31T17:51:25.259+0000] {taskinstance.py:2648} INFO - Exporting env vars: AIRFLOW_CTX_DAG_EMAIL='jorgepons90@gmail.com,facturasjorgepons@gmail.com' AIRFLOW_CTX_DAG_OWNER='Jorge Pons' AIRFLOW_CTX_DAG_ID='simple_dag' AIRFLOW_CTX_TASK_ID='execution_time' AIRFLOW_CTX_EXECUTION_DATE='2024-08-31T16:50:00.890695+00:00' AIRFLOW_CTX_TRY_NUMBER='20' AIRFLOW_CTX_DAG_RUN_ID='manual__2024-08-31T16:50:00.890695+00:00'
[2024-08-31T17:51:25.262+0000] {taskinstance.py:430} INFO - ::endgroup::
[2024-08-31T17:51:25.289+0000] {taskinstance.py:441} INFO - ::group::Post task execution logs
[2024-08-31T17:51:25.291+0000] {taskinstance.py:2905} ERROR - Task failed with exception
Traceback (most recent call last):
  File "/home/airflow/.local/lib/python3.12/site-packages/airflow/models/taskinstance.py", line 465, in _execute_task
    result = _execute_callable(context=context, **execute_callable_kwargs)
             ^^^^^^^^^^^^^^^^^^^^^^^^^^^^^^^^^^^^^^^^^^^^^^^^^^^^^^^^^^^^^
  File "/home/airflow/.local/lib/python3.12/site-packages/airflow/models/taskinstance.py", line 432, in _execute_callable
    return execute_callable(context=context, **execute_callable_kwargs)
           ^^^^^^^^^^^^^^^^^^^^^^^^^^^^^^^^^^^^^^^^^^^^^^^^^^^^^^^^^^^^
  File "/home/airflow/.local/lib/python3.12/site-packages/airflow/models/baseoperator.py", line 401, in wrapper
    return func(self, *args, **kwargs)
           ^^^^^^^^^^^^^^^^^^^^^^^^^^^
  File "/home/airflow/.local/lib/python3.12/site-packages/airflow/operators/python.py", line 235, in execute
    return_value = self.execute_callable()
                   ^^^^^^^^^^^^^^^^^^^^^^^
  File "/home/airflow/.local/lib/python3.12/site-packages/airflow/operators/python.py", line 252, in execute_callable
    return self.python_callable(*self.op_args, **self.op_kwargs)
           ^^^^^^^^^^^^^^^^^^^^^^^^^^^^^^^^^^^^^^^^^^^^^^^^^^^^^
  File "/opt/airflow/dags/funciones.py", line 217, in insertar_tiempo_ejecucion
    duration = pd.to_datetime(duration)
               ^^^^^^^^^^^^^^^^^^^^^^^^
  File "/home/airflow/.local/lib/python3.12/site-packages/pandas/core/tools/datetimes.py", line 1146, in to_datetime
    result = convert_listlike(np.array([arg]), format)[0]
             ^^^^^^^^^^^^^^^^^^^^^^^^^^^^^^^^^^^^^^^^^
  File "/home/airflow/.local/lib/python3.12/site-packages/pandas/core/tools/datetimes.py", line 490, in _convert_listlike_datetimes
    result, tz_parsed = objects_to_datetime64ns(
                        ^^^^^^^^^^^^^^^^^^^^^^^^
  File "/home/airflow/.local/lib/python3.12/site-packages/pandas/core/arrays/datetimes.py", line 2346, in objects_to_datetime64ns
    result, tz_parsed = tslib.array_to_datetime(
                        ^^^^^^^^^^^^^^^^^^^^^^^^
  File "tslib.pyx", line 403, in pandas._libs.tslib.array_to_datetime
  File "tslib.pyx", line 552, in pandas._libs.tslib.array_to_datetime
  File "tslib.pyx", line 541, in pandas._libs.tslib.array_to_datetime
TypeError: <class 'datetime.timedelta'> is not convertible to datetime, at position 0
[2024-08-31T17:51:25.314+0000] {taskinstance.py:1206} INFO - Marking task as UP_FOR_RETRY. dag_id=simple_dag, task_id=execution_time, run_id=manual__2024-08-31T16:50:00.890695+00:00, execution_date=20240831T165000, start_date=20240831T175124, end_date=20240831T175125
[2024-08-31T17:51:25.336+0000] {standard_task_runner.py:110} ERROR - Failed to execute job 350 for task execution_time (<class 'datetime.timedelta'> is not convertible to datetime, at position 0; 3293)
[2024-08-31T17:51:25.380+0000] {local_task_job_runner.py:243} INFO - Task exited with return code 1
[2024-08-31T17:51:25.414+0000] {taskinstance.py:3503} INFO - 0 downstream tasks scheduled from follow-on schedule check
[2024-08-31T17:51:25.418+0000] {local_task_job_runner.py:222} INFO - ::endgroup::
